[2023-02-10 07:16:46,761] {taskinstance.py:1032} INFO - Dependencies all met for <TaskInstance: tutorial.launching_chrome manual__2023-02-10T07:16:44.132852+00:00 [queued]>
[2023-02-10 07:16:46,781] {taskinstance.py:1032} INFO - Dependencies all met for <TaskInstance: tutorial.launching_chrome manual__2023-02-10T07:16:44.132852+00:00 [queued]>
[2023-02-10 07:16:46,782] {taskinstance.py:1238} INFO - 
--------------------------------------------------------------------------------
[2023-02-10 07:16:46,783] {taskinstance.py:1239} INFO - Starting attempt 1 of 2
[2023-02-10 07:16:46,784] {taskinstance.py:1240} INFO - 
--------------------------------------------------------------------------------
[2023-02-10 07:16:46,803] {taskinstance.py:1259} INFO - Executing <Task(_PythonDecoratedOperator): launching_chrome> on 2023-02-10 07:16:44.132852+00:00
[2023-02-10 07:16:46,809] {standard_task_runner.py:52} INFO - Started process 1658 to run task
[2023-02-10 07:16:46,817] {standard_task_runner.py:76} INFO - Running: ['***', 'tasks', 'run', 'tutorial', 'launching_chrome', 'manual__2023-02-10T07:16:44.132852+00:00', '--job-id', '8', '--raw', '--subdir', 'DAGS_FOLDER/reddit_ingestion_dag.py', '--cfg-path', '/tmp/tmp0mhdbyvt', '--error-file', '/tmp/tmp5c6z5sjc']
[2023-02-10 07:16:46,819] {standard_task_runner.py:77} INFO - Job 8: Subtask launching_chrome
[2023-02-10 07:16:46,930] {logging_mixin.py:109} INFO - Running <TaskInstance: tutorial.launching_chrome manual__2023-02-10T07:16:44.132852+00:00 [running]> on host e8bcd8791230
[2023-02-10 07:16:47,004] {taskinstance.py:1426} INFO - Exporting the following env vars:
AIRFLOW_CTX_DAG_EMAIL=***@example.com
AIRFLOW_CTX_DAG_OWNER=***
AIRFLOW_CTX_DAG_ID=tutorial
AIRFLOW_CTX_TASK_ID=launching_chrome
AIRFLOW_CTX_EXECUTION_DATE=2023-02-10T07:16:44.132852+00:00
AIRFLOW_CTX_DAG_RUN_ID=manual__2023-02-10T07:16:44.132852+00:00
[2023-02-10 07:16:47,041] {taskinstance.py:1700} ERROR - Task failed with exception
Traceback (most recent call last):
  File "/home/airflow/.local/lib/python3.7/site-packages/selenium/webdriver/common/service.py", line 95, in start
    path = SeleniumManager().driver_location(browser)
  File "/home/airflow/.local/lib/python3.7/site-packages/selenium/webdriver/common/selenium_manager.py", line 74, in driver_location
    result = self.run((binary, flag, browser))
  File "/home/airflow/.local/lib/python3.7/site-packages/selenium/webdriver/common/selenium_manager.py", line 93, in run
    raise SeleniumManagerException(f"Selenium manager failed for: {command}.\n{stdout}{stderr}")
selenium.common.exceptions.SeleniumManagerException: Message: Selenium manager failed for: /home/airflow/.local/lib/python3.7/site-packages/selenium/webdriver/common/linux/selenium-manager --browser chrome.
/home/airflow/.local/lib/python3.7/site-packages/selenium/webdriver/common/linux/selenium-manager: /lib/x86_64-linux-gnu/libc.so.6: version `GLIBC_2.29' not found (required by /home/airflow/.local/lib/python3.7/site-packages/selenium/webdriver/common/linux/selenium-manager)


During handling of the above exception, another exception occurred:

Traceback (most recent call last):
  File "/home/airflow/.local/lib/python3.7/site-packages/airflow/models/taskinstance.py", line 1329, in _run_raw_task
    self._execute_task_with_callbacks(context)
  File "/home/airflow/.local/lib/python3.7/site-packages/airflow/models/taskinstance.py", line 1455, in _execute_task_with_callbacks
    result = self._execute_task(context, self.task)
  File "/home/airflow/.local/lib/python3.7/site-packages/airflow/models/taskinstance.py", line 1511, in _execute_task
    result = execute_callable(context=context)
  File "/home/airflow/.local/lib/python3.7/site-packages/airflow/decorators/base.py", line 134, in execute
    return_value = super().execute(context)
  File "/home/airflow/.local/lib/python3.7/site-packages/airflow/operators/python.py", line 174, in execute
    return_value = self.execute_callable()
  File "/home/airflow/.local/lib/python3.7/site-packages/airflow/operators/python.py", line 185, in execute_callable
    return self.python_callable(*self.op_args, **self.op_kwargs)
  File "/opt/airflow/dags/reddit_ingestion_dag.py", line 117, in launch_chrome
    driver = webdriver.Chrome("/Users/raolu/airflow-docker/chromedriver")
  File "/home/airflow/.local/lib/python3.7/site-packages/selenium/webdriver/chrome/webdriver.py", line 89, in __init__
    keep_alive,
  File "/home/airflow/.local/lib/python3.7/site-packages/selenium/webdriver/chromium/webdriver.py", line 101, in __init__
    self.service.start()
  File "/home/airflow/.local/lib/python3.7/site-packages/selenium/webdriver/common/service.py", line 98, in start
    raise err
  File "/home/airflow/.local/lib/python3.7/site-packages/selenium/webdriver/common/service.py", line 88, in start
    self._start_process(self.path)
  File "/home/airflow/.local/lib/python3.7/site-packages/selenium/webdriver/common/service.py", line 210, in _start_process
    f"'{os.path.basename(self.path)}' executable needs to be in PATH. {self.start_error_message}"
selenium.common.exceptions.WebDriverException: Message: 'chromedriver' executable needs to be in PATH. Please see https://chromedriver.chromium.org/home

[2023-02-10 07:16:47,076] {taskinstance.py:1277} INFO - Marking task as UP_FOR_RETRY. dag_id=tutorial, task_id=launching_chrome, execution_date=20230210T071644, start_date=20230210T071646, end_date=20230210T071647
[2023-02-10 07:16:47,102] {standard_task_runner.py:92} ERROR - Failed to execute job 8 for task launching_chrome
Traceback (most recent call last):
  File "/home/airflow/.local/lib/python3.7/site-packages/selenium/webdriver/common/service.py", line 95, in start
    path = SeleniumManager().driver_location(browser)
  File "/home/airflow/.local/lib/python3.7/site-packages/selenium/webdriver/common/selenium_manager.py", line 74, in driver_location
    result = self.run((binary, flag, browser))
  File "/home/airflow/.local/lib/python3.7/site-packages/selenium/webdriver/common/selenium_manager.py", line 93, in run
    raise SeleniumManagerException(f"Selenium manager failed for: {command}.\n{stdout}{stderr}")
selenium.common.exceptions.SeleniumManagerException: Message: Selenium manager failed for: /home/airflow/.local/lib/python3.7/site-packages/selenium/webdriver/common/linux/selenium-manager --browser chrome.
/home/airflow/.local/lib/python3.7/site-packages/selenium/webdriver/common/linux/selenium-manager: /lib/x86_64-linux-gnu/libc.so.6: version `GLIBC_2.29' not found (required by /home/airflow/.local/lib/python3.7/site-packages/selenium/webdriver/common/linux/selenium-manager)


During handling of the above exception, another exception occurred:

Traceback (most recent call last):
  File "/home/airflow/.local/lib/python3.7/site-packages/airflow/task/task_runner/standard_task_runner.py", line 85, in _start_by_fork
    args.func(args, dag=self.dag)
  File "/home/airflow/.local/lib/python3.7/site-packages/airflow/cli/cli_parser.py", line 48, in command
    return func(*args, **kwargs)
  File "/home/airflow/.local/lib/python3.7/site-packages/airflow/utils/cli.py", line 92, in wrapper
    return f(*args, **kwargs)
  File "/home/airflow/.local/lib/python3.7/site-packages/airflow/cli/commands/task_command.py", line 298, in task_run
    _run_task_by_selected_method(args, dag, ti)
  File "/home/airflow/.local/lib/python3.7/site-packages/airflow/cli/commands/task_command.py", line 107, in _run_task_by_selected_method
    _run_raw_task(args, ti)
  File "/home/airflow/.local/lib/python3.7/site-packages/airflow/cli/commands/task_command.py", line 184, in _run_raw_task
    error_file=args.error_file,
  File "/home/airflow/.local/lib/python3.7/site-packages/airflow/utils/session.py", line 70, in wrapper
    return func(*args, session=session, **kwargs)
  File "/home/airflow/.local/lib/python3.7/site-packages/airflow/models/taskinstance.py", line 1329, in _run_raw_task
    self._execute_task_with_callbacks(context)
  File "/home/airflow/.local/lib/python3.7/site-packages/airflow/models/taskinstance.py", line 1455, in _execute_task_with_callbacks
    result = self._execute_task(context, self.task)
  File "/home/airflow/.local/lib/python3.7/site-packages/airflow/models/taskinstance.py", line 1511, in _execute_task
    result = execute_callable(context=context)
  File "/home/airflow/.local/lib/python3.7/site-packages/airflow/decorators/base.py", line 134, in execute
    return_value = super().execute(context)
  File "/home/airflow/.local/lib/python3.7/site-packages/airflow/operators/python.py", line 174, in execute
    return_value = self.execute_callable()
  File "/home/airflow/.local/lib/python3.7/site-packages/airflow/operators/python.py", line 185, in execute_callable
    return self.python_callable(*self.op_args, **self.op_kwargs)
  File "/opt/airflow/dags/reddit_ingestion_dag.py", line 117, in launch_chrome
    driver = webdriver.Chrome("/Users/raolu/airflow-docker/chromedriver")
  File "/home/airflow/.local/lib/python3.7/site-packages/selenium/webdriver/chrome/webdriver.py", line 89, in __init__
    keep_alive,
  File "/home/airflow/.local/lib/python3.7/site-packages/selenium/webdriver/chromium/webdriver.py", line 101, in __init__
    self.service.start()
  File "/home/airflow/.local/lib/python3.7/site-packages/selenium/webdriver/common/service.py", line 98, in start
    raise err
  File "/home/airflow/.local/lib/python3.7/site-packages/selenium/webdriver/common/service.py", line 88, in start
    self._start_process(self.path)
  File "/home/airflow/.local/lib/python3.7/site-packages/selenium/webdriver/common/service.py", line 210, in _start_process
    f"'{os.path.basename(self.path)}' executable needs to be in PATH. {self.start_error_message}"
selenium.common.exceptions.WebDriverException: Message: 'chromedriver' executable needs to be in PATH. Please see https://chromedriver.chromium.org/home

[2023-02-10 07:16:47,153] {local_task_job.py:154} INFO - Task exited with return code 1
[2023-02-10 07:16:47,190] {local_task_job.py:264} INFO - 0 downstream tasks scheduled from follow-on schedule check
