[2023-02-11 00:02:00,233] {taskinstance.py:1032} INFO - Dependencies all met for <TaskInstance: tutorial.launching_chrome manual__2023-02-10T23:56:55.569045+00:00 [queued]>
[2023-02-11 00:02:00,249] {taskinstance.py:1032} INFO - Dependencies all met for <TaskInstance: tutorial.launching_chrome manual__2023-02-10T23:56:55.569045+00:00 [queued]>
[2023-02-11 00:02:00,250] {taskinstance.py:1238} INFO - 
--------------------------------------------------------------------------------
[2023-02-11 00:02:00,251] {taskinstance.py:1239} INFO - Starting attempt 2 of 2
[2023-02-11 00:02:00,252] {taskinstance.py:1240} INFO - 
--------------------------------------------------------------------------------
[2023-02-11 00:02:00,268] {taskinstance.py:1259} INFO - Executing <Task(_PythonDecoratedOperator): launching_chrome> on 2023-02-10 23:56:55.569045+00:00
[2023-02-11 00:02:00,274] {standard_task_runner.py:52} INFO - Started process 3402 to run task
[2023-02-11 00:02:00,280] {standard_task_runner.py:76} INFO - Running: ['***', 'tasks', 'run', 'tutorial', 'launching_chrome', 'manual__2023-02-10T23:56:55.569045+00:00', '--job-id', '96', '--raw', '--subdir', 'DAGS_FOLDER/reddit_ingestion_dag.py', '--cfg-path', '/tmp/tmpbln82gle', '--error-file', '/tmp/tmpqtz7d46g']
[2023-02-11 00:02:00,282] {standard_task_runner.py:77} INFO - Job 96: Subtask launching_chrome
[2023-02-11 00:02:00,388] {logging_mixin.py:109} INFO - Running <TaskInstance: tutorial.launching_chrome manual__2023-02-10T23:56:55.569045+00:00 [running]> on host 2212ae742bae
[2023-02-11 00:02:00,468] {taskinstance.py:1426} INFO - Exporting the following env vars:
AIRFLOW_CTX_DAG_EMAIL=***@example.com
AIRFLOW_CTX_DAG_OWNER=***
AIRFLOW_CTX_DAG_ID=tutorial
AIRFLOW_CTX_TASK_ID=launching_chrome
AIRFLOW_CTX_EXECUTION_DATE=2023-02-10T23:56:55.569045+00:00
AIRFLOW_CTX_DAG_RUN_ID=manual__2023-02-10T23:56:55.569045+00:00
[2023-02-11 00:02:00,476] {connectionpool.py:781} WARNING - Retrying (Retry(total=2, connect=None, read=None, redirect=None, status=None)) after connection broken by 'NewConnectionError('<urllib3.connection.HTTPConnection object at 0x7f99e4a590d0>: Failed to establish a new connection: [Errno 111] Connection refused')': /wd/hub/session
[2023-02-11 00:02:00,478] {connectionpool.py:781} WARNING - Retrying (Retry(total=1, connect=None, read=None, redirect=None, status=None)) after connection broken by 'NewConnectionError('<urllib3.connection.HTTPConnection object at 0x7f99f71f3d10>: Failed to establish a new connection: [Errno 111] Connection refused')': /wd/hub/session
[2023-02-11 00:02:00,480] {connectionpool.py:781} WARNING - Retrying (Retry(total=0, connect=None, read=None, redirect=None, status=None)) after connection broken by 'NewConnectionError('<urllib3.connection.HTTPConnection object at 0x7f99e4a4c410>: Failed to establish a new connection: [Errno 111] Connection refused')': /wd/hub/session
[2023-02-11 00:02:00,483] {taskinstance.py:1700} ERROR - Task failed with exception
Traceback (most recent call last):
  File "/home/airflow/.local/lib/python3.7/site-packages/urllib3/connection.py", line 175, in _new_conn
    (self._dns_host, self.port), self.timeout, **extra_kw
  File "/home/airflow/.local/lib/python3.7/site-packages/urllib3/util/connection.py", line 96, in create_connection
    raise err
  File "/home/airflow/.local/lib/python3.7/site-packages/urllib3/util/connection.py", line 86, in create_connection
    sock.connect(sa)
ConnectionRefusedError: [Errno 111] Connection refused

During handling of the above exception, another exception occurred:

Traceback (most recent call last):
  File "/home/airflow/.local/lib/python3.7/site-packages/urllib3/connectionpool.py", line 706, in urlopen
    chunked=chunked,
  File "/home/airflow/.local/lib/python3.7/site-packages/urllib3/connectionpool.py", line 394, in _make_request
    conn.request(method, url, **httplib_request_kw)
  File "/home/airflow/.local/lib/python3.7/site-packages/urllib3/connection.py", line 239, in request
    super(HTTPConnection, self).request(method, url, body=body, headers=headers)
  File "/usr/local/lib/python3.7/http/client.py", line 1281, in request
    self._send_request(method, url, body, headers, encode_chunked)
  File "/usr/local/lib/python3.7/http/client.py", line 1327, in _send_request
    self.endheaders(body, encode_chunked=encode_chunked)
  File "/usr/local/lib/python3.7/http/client.py", line 1276, in endheaders
    self._send_output(message_body, encode_chunked=encode_chunked)
  File "/usr/local/lib/python3.7/http/client.py", line 1036, in _send_output
    self.send(msg)
  File "/usr/local/lib/python3.7/http/client.py", line 976, in send
    self.connect()
  File "/home/airflow/.local/lib/python3.7/site-packages/urllib3/connection.py", line 205, in connect
    conn = self._new_conn()
  File "/home/airflow/.local/lib/python3.7/site-packages/urllib3/connection.py", line 187, in _new_conn
    self, "Failed to establish a new connection: %s" % e
urllib3.exceptions.NewConnectionError: <urllib3.connection.HTTPConnection object at 0x7f99e4a4c310>: Failed to establish a new connection: [Errno 111] Connection refused

During handling of the above exception, another exception occurred:

Traceback (most recent call last):
  File "/home/airflow/.local/lib/python3.7/site-packages/airflow/models/taskinstance.py", line 1329, in _run_raw_task
    self._execute_task_with_callbacks(context)
  File "/home/airflow/.local/lib/python3.7/site-packages/airflow/models/taskinstance.py", line 1455, in _execute_task_with_callbacks
    result = self._execute_task(context, self.task)
  File "/home/airflow/.local/lib/python3.7/site-packages/airflow/models/taskinstance.py", line 1511, in _execute_task
    result = execute_callable(context=context)
  File "/home/airflow/.local/lib/python3.7/site-packages/airflow/decorators/base.py", line 134, in execute
    return_value = super().execute(context)
  File "/home/airflow/.local/lib/python3.7/site-packages/airflow/operators/python.py", line 174, in execute
    return_value = self.execute_callable()
  File "/home/airflow/.local/lib/python3.7/site-packages/airflow/operators/python.py", line 185, in execute_callable
    return self.python_callable(*self.op_args, **self.op_kwargs)
  File "/opt/airflow/dags/reddit_ingestion_dag.py", line 132, in launch_chrome
    driver = webdriver.Remote(command_executor="http://localhost:4444/wd/hub", options=options)
  File "/home/airflow/.local/lib/python3.7/site-packages/selenium/webdriver/remote/webdriver.py", line 286, in __init__
    self.start_session(capabilities, browser_profile)
  File "/home/airflow/.local/lib/python3.7/site-packages/selenium/webdriver/remote/webdriver.py", line 378, in start_session
    response = self.execute(Command.NEW_SESSION, parameters)
  File "/home/airflow/.local/lib/python3.7/site-packages/selenium/webdriver/remote/webdriver.py", line 438, in execute
    response = self.command_executor.execute(driver_command, params)
  File "/home/airflow/.local/lib/python3.7/site-packages/selenium/webdriver/remote/remote_connection.py", line 290, in execute
    return self._request(command_info[0], url, body=data)
  File "/home/airflow/.local/lib/python3.7/site-packages/selenium/webdriver/remote/remote_connection.py", line 311, in _request
    response = self._conn.request(method, url, body=body, headers=headers)
  File "/home/airflow/.local/lib/python3.7/site-packages/urllib3/request.py", line 79, in request
    method, url, fields=fields, headers=headers, **urlopen_kw
  File "/home/airflow/.local/lib/python3.7/site-packages/urllib3/request.py", line 170, in request_encode_body
    return self.urlopen(method, url, **extra_kw)
  File "/home/airflow/.local/lib/python3.7/site-packages/urllib3/poolmanager.py", line 375, in urlopen
    response = conn.urlopen(method, u.request_uri, **kw)
  File "/home/airflow/.local/lib/python3.7/site-packages/urllib3/connectionpool.py", line 796, in urlopen
    **response_kw
  File "/home/airflow/.local/lib/python3.7/site-packages/urllib3/connectionpool.py", line 796, in urlopen
    **response_kw
  File "/home/airflow/.local/lib/python3.7/site-packages/urllib3/connectionpool.py", line 796, in urlopen
    **response_kw
  File "/home/airflow/.local/lib/python3.7/site-packages/urllib3/connectionpool.py", line 756, in urlopen
    method, url, error=e, _pool=self, _stacktrace=sys.exc_info()[2]
  File "/home/airflow/.local/lib/python3.7/site-packages/urllib3/util/retry.py", line 574, in increment
    raise MaxRetryError(_pool, url, error or ResponseError(cause))
urllib3.exceptions.MaxRetryError: HTTPConnectionPool(host='localhost', port=4444): Max retries exceeded with url: /wd/hub/session (Caused by NewConnectionError('<urllib3.connection.HTTPConnection object at 0x7f99e4a4c310>: Failed to establish a new connection: [Errno 111] Connection refused'))
[2023-02-11 00:02:00,507] {taskinstance.py:1277} INFO - Marking task as FAILED. dag_id=tutorial, task_id=launching_chrome, execution_date=20230210T235655, start_date=20230211T000200, end_date=20230211T000200
[2023-02-11 00:02:00,527] {standard_task_runner.py:92} ERROR - Failed to execute job 96 for task launching_chrome
Traceback (most recent call last):
  File "/home/airflow/.local/lib/python3.7/site-packages/urllib3/connection.py", line 175, in _new_conn
    (self._dns_host, self.port), self.timeout, **extra_kw
  File "/home/airflow/.local/lib/python3.7/site-packages/urllib3/util/connection.py", line 96, in create_connection
    raise err
  File "/home/airflow/.local/lib/python3.7/site-packages/urllib3/util/connection.py", line 86, in create_connection
    sock.connect(sa)
ConnectionRefusedError: [Errno 111] Connection refused

During handling of the above exception, another exception occurred:

Traceback (most recent call last):
  File "/home/airflow/.local/lib/python3.7/site-packages/urllib3/connectionpool.py", line 706, in urlopen
    chunked=chunked,
  File "/home/airflow/.local/lib/python3.7/site-packages/urllib3/connectionpool.py", line 394, in _make_request
    conn.request(method, url, **httplib_request_kw)
  File "/home/airflow/.local/lib/python3.7/site-packages/urllib3/connection.py", line 239, in request
    super(HTTPConnection, self).request(method, url, body=body, headers=headers)
  File "/usr/local/lib/python3.7/http/client.py", line 1281, in request
    self._send_request(method, url, body, headers, encode_chunked)
  File "/usr/local/lib/python3.7/http/client.py", line 1327, in _send_request
    self.endheaders(body, encode_chunked=encode_chunked)
  File "/usr/local/lib/python3.7/http/client.py", line 1276, in endheaders
    self._send_output(message_body, encode_chunked=encode_chunked)
  File "/usr/local/lib/python3.7/http/client.py", line 1036, in _send_output
    self.send(msg)
  File "/usr/local/lib/python3.7/http/client.py", line 976, in send
    self.connect()
  File "/home/airflow/.local/lib/python3.7/site-packages/urllib3/connection.py", line 205, in connect
    conn = self._new_conn()
  File "/home/airflow/.local/lib/python3.7/site-packages/urllib3/connection.py", line 187, in _new_conn
    self, "Failed to establish a new connection: %s" % e
urllib3.exceptions.NewConnectionError: <urllib3.connection.HTTPConnection object at 0x7f99e4a4c310>: Failed to establish a new connection: [Errno 111] Connection refused

During handling of the above exception, another exception occurred:

Traceback (most recent call last):
  File "/home/airflow/.local/lib/python3.7/site-packages/airflow/task/task_runner/standard_task_runner.py", line 85, in _start_by_fork
    args.func(args, dag=self.dag)
  File "/home/airflow/.local/lib/python3.7/site-packages/airflow/cli/cli_parser.py", line 48, in command
    return func(*args, **kwargs)
  File "/home/airflow/.local/lib/python3.7/site-packages/airflow/utils/cli.py", line 92, in wrapper
    return f(*args, **kwargs)
  File "/home/airflow/.local/lib/python3.7/site-packages/airflow/cli/commands/task_command.py", line 298, in task_run
    _run_task_by_selected_method(args, dag, ti)
  File "/home/airflow/.local/lib/python3.7/site-packages/airflow/cli/commands/task_command.py", line 107, in _run_task_by_selected_method
    _run_raw_task(args, ti)
  File "/home/airflow/.local/lib/python3.7/site-packages/airflow/cli/commands/task_command.py", line 184, in _run_raw_task
    error_file=args.error_file,
  File "/home/airflow/.local/lib/python3.7/site-packages/airflow/utils/session.py", line 70, in wrapper
    return func(*args, session=session, **kwargs)
  File "/home/airflow/.local/lib/python3.7/site-packages/airflow/models/taskinstance.py", line 1329, in _run_raw_task
    self._execute_task_with_callbacks(context)
  File "/home/airflow/.local/lib/python3.7/site-packages/airflow/models/taskinstance.py", line 1455, in _execute_task_with_callbacks
    result = self._execute_task(context, self.task)
  File "/home/airflow/.local/lib/python3.7/site-packages/airflow/models/taskinstance.py", line 1511, in _execute_task
    result = execute_callable(context=context)
  File "/home/airflow/.local/lib/python3.7/site-packages/airflow/decorators/base.py", line 134, in execute
    return_value = super().execute(context)
  File "/home/airflow/.local/lib/python3.7/site-packages/airflow/operators/python.py", line 174, in execute
    return_value = self.execute_callable()
  File "/home/airflow/.local/lib/python3.7/site-packages/airflow/operators/python.py", line 185, in execute_callable
    return self.python_callable(*self.op_args, **self.op_kwargs)
  File "/opt/airflow/dags/reddit_ingestion_dag.py", line 132, in launch_chrome
    driver = webdriver.Remote(command_executor="http://localhost:4444/wd/hub", options=options)
  File "/home/airflow/.local/lib/python3.7/site-packages/selenium/webdriver/remote/webdriver.py", line 286, in __init__
    self.start_session(capabilities, browser_profile)
  File "/home/airflow/.local/lib/python3.7/site-packages/selenium/webdriver/remote/webdriver.py", line 378, in start_session
    response = self.execute(Command.NEW_SESSION, parameters)
  File "/home/airflow/.local/lib/python3.7/site-packages/selenium/webdriver/remote/webdriver.py", line 438, in execute
    response = self.command_executor.execute(driver_command, params)
  File "/home/airflow/.local/lib/python3.7/site-packages/selenium/webdriver/remote/remote_connection.py", line 290, in execute
    return self._request(command_info[0], url, body=data)
  File "/home/airflow/.local/lib/python3.7/site-packages/selenium/webdriver/remote/remote_connection.py", line 311, in _request
    response = self._conn.request(method, url, body=body, headers=headers)
  File "/home/airflow/.local/lib/python3.7/site-packages/urllib3/request.py", line 79, in request
    method, url, fields=fields, headers=headers, **urlopen_kw
  File "/home/airflow/.local/lib/python3.7/site-packages/urllib3/request.py", line 170, in request_encode_body
    return self.urlopen(method, url, **extra_kw)
  File "/home/airflow/.local/lib/python3.7/site-packages/urllib3/poolmanager.py", line 375, in urlopen
    response = conn.urlopen(method, u.request_uri, **kw)
  File "/home/airflow/.local/lib/python3.7/site-packages/urllib3/connectionpool.py", line 796, in urlopen
    **response_kw
  File "/home/airflow/.local/lib/python3.7/site-packages/urllib3/connectionpool.py", line 796, in urlopen
    **response_kw
  File "/home/airflow/.local/lib/python3.7/site-packages/urllib3/connectionpool.py", line 796, in urlopen
    **response_kw
  File "/home/airflow/.local/lib/python3.7/site-packages/urllib3/connectionpool.py", line 756, in urlopen
    method, url, error=e, _pool=self, _stacktrace=sys.exc_info()[2]
  File "/home/airflow/.local/lib/python3.7/site-packages/urllib3/util/retry.py", line 574, in increment
    raise MaxRetryError(_pool, url, error or ResponseError(cause))
urllib3.exceptions.MaxRetryError: HTTPConnectionPool(host='localhost', port=4444): Max retries exceeded with url: /wd/hub/session (Caused by NewConnectionError('<urllib3.connection.HTTPConnection object at 0x7f99e4a4c310>: Failed to establish a new connection: [Errno 111] Connection refused'))
[2023-02-11 00:02:00,575] {local_task_job.py:154} INFO - Task exited with return code 1
[2023-02-11 00:02:00,623] {local_task_job.py:264} INFO - 0 downstream tasks scheduled from follow-on schedule check
